Workbook
Name Slicer_Representative: #N/A
Name Slicer_Representative1: #N/A
Name Slicer_Representative2: #N/A

Sheet Raw Data
B1: Call Centre Data
B3: Call number | C3: Customer ID | D3: Duration | E3: Representative | F3: Date of Call | G3: Purchase Amount | H3: Satisfaction Rating
B4: Call_7271 | C4: C0003 | D4: 116 | E4: R05 | F4: 44927 | G4: 128 | H4: 4.9
B5: Call_7272 | C5: C0004 | D5: 119 | E5: R05 | F5: 44927 | G5: 135 | H5: 2.9
B6: Call_7273 | C6: C0005 | D6: 68 | E6: R02 | F6: 44927 | G6: 66 | H6: 4.7
B7: Call_7274 | C7: C0014 | D7: 119 | E7: R02 | F7: 44927 | G7: 22 | H7: 2.9
B8: Call_7275 | C8: C0011 | D8: 128 | E8: R01 | F8: 44928 | G8: 31 | H8: 2.8
B9: Call_7276 | C9: C0011 | D9: 49 | E9: R02 | F9: 44929 | G9: 135 | H9: 4.8
B10: Call_7277 | C10: C0007 | D10: 84 | E10: R05 | F10: 44929 | G10: 60 | H10: 4.7
B11: Call_7278 | C11: C0003 | D11: 103 | E11: R04 | F11: 44929 | G11: 148 | H11: 4.4
B12: Call_7279 | C12: C0005 | D12: 31 | E12: R02 | F12: 44929 | G12: 135 | H12: 3.6
B13: Call_7280 | C13: C0010 | D13: 44 | E13: R03 | F13: 44929 | G13: 105 | H13: 2.9
B14: Call_7281 | C14: C0011 | D14: 102 | E14: R02 | F14: 44929 | G14: 69 | H14: 4.9
B15: Call_7282 | C15: C0013 | D15: 135 | E15: R05 | F15: 44929 | G15: 46 | H15: 3.4
... B1003: Call_8270 | C1003: C0009 | D1003: 114 | E1003: R01 | F1003: 45291 | G1003: 40 | H1003: 3.9

Sheet Call Table
A1: Call_Number | B1: Customer_ID | C1: Call_Duration | D1: Representative | E1: Purchase_Amount | F1: Satisfaction_Rating | G1: Call_Date | H1: Year | I1: Quarter | J1: Month_Number | K1: Month_Name | L1: Weekday | M1: FY | N1: Duration_Bucket | O1: Rating_Rounded
A2: Call_7271 | B2: C0003 | C2: 116 | D2: R05 | E2: 128 | F2: 4.9 | G2: 44927 | H2: 2023 | I2: 1 | J2: 1 | K2: January | L2: Sunday | M2: 2023 | N2: 1 to 2 hours | O2: 5
A3: Call_7272 | B3: C0004 | C3: 119 | D3: R05 | E3: 135 | F3: 2.9 | G3: 44927 | H3: 2023 | I3: 1 | J3: 1 | K3: January | L3: Sunday | M3: 2023 | N3: 1 to 2 hours | O3: 3
A4: Call_7273 | B4: C0005 | C4: 68 | D4: R02 | E4: 66 | F4: 4.7 | G4: 44927 | H4: 2023 | I4: 1 | J4: 1 | K4: January | L4: Sunday | M4: 2023 | N4: 1 to 2 hours | O4: 5
A5: Call_7274 | B5: C0014 | C5: 119 | D5: R02 | E5: 22 | F5: 2.9 | G5: 44927 | H5: 2023 | I5: 1 | J5: 1 | K5: January | L5: Sunday | M5: 2023 | N5: 1 to 2 hours | O5: 3
A6: Call_7275 | B6: C0011 | C6: 128 | D6: R01 | E6: 31 | F6: 2.8 | G6: 44928 | H6: 2023 | I6: 1 | J6: 1 | K6: January | L6: Monday | M6: 2023 | N6: More than 2 hours | O6: 3
A7: Call_7276 | B7: C0011 | C7: 49 | D7: R02 | E7: 135 | F7: 4.8 | G7: 44929 | H7: 2023 | I7: 1 | J7: 1 | K7: January | L7: Tuesday | M7: 2023 | N7: 30 to 60 mins | O7: 5
A8: Call_7277 | B8: C0007 | C8: 84 | D8: R05 | E8: 60 | F8: 4.7 | G8: 44929 | H8: 2023 | I8: 1 | J8: 1 | K8: January | L8: Tuesday | M8: 2023 | N8: 1 to 2 hours | O8: 5
A9: Call_7278 | B9: C0003 | C9: 103 | D9: R04 | E9: 148 | F9: 4.4 | G9: 44929 | H9: 2023 | I9: 1 | J9: 1 | K9: January | L9: Tuesday | M9: 2023 | N9: 1 to 2 hours | O9: 4
A10: Call_7279 | B10: C0005 | C10: 31 | D10: R02 | E10: 135 | F10: 3.6 | G10: 44929 | H10: 2023 | I10: 1 | J10: 1 | K10: January | L10: Tuesday | M10: 2023 | N10: 30 to 60 mins | O10: 4
A11: Call_7280 | B11: C0010 | C11: 44 | D11: R03 | E11: 105 | F11: 2.9 | G11: 44929 | H11: 2023 | I11: 1 | J11: 1 | K11: January | L11: Tuesday | M11: 2023 | N11: 30 to 60 mins | O11: 3
A12: Call_7281 | B12: C0011 | C12: 102 | D12: R02 | E12: 69 | F12: 4.9 | G12: 44929 | H12: 2023 | I12: 1 | J12: 1 | K12: January | L12: Tuesday | M12: 2023 | N12: 1 to 2 hours | O12: 5
A13: Call_7282 | B13: C0013 | C13: 135 | D13: R05 | E13: 46 | F13: 3.4 | G13: 44929 | H13: 2023 | I13: 1 | J13: 1 | K13: January | L13: Tuesday | M13: 2023 | N13: More than 2 hours | O13: 3
... A997: Call_8270 | B997: C0009 | C997: 114 | D997: R01 | E997: 40 | F997: 3.9 | G997: 45291 | H997: 2023 | I997: 4 | J997: 12 | K997: December | L997: Sunday | M997: 2024 | N997: 1 to 2 hours | O997: 4

Sheet Customer Table
A1: Customer ID | B1: Gedner | C1: Age | D1: City
A2: C0001 | B2: Male | C2: 41 | D2: Columbus
A3: C0002 | B3: Male | C3: 31 | D3: Cleveland
A4: C0003 | B4: Male | C4: 26 | D4: Cincinnati
A5: C0004 | B5: Male | C5: 36 | D5: Cincinnati
A6: C0005 | B6: Male | C6: 37 | D6: Columbus
A7: C0006 | B7: Male | C7: 23 | D7: Columbus
A8: C0007 | B8: Female | C8: 22 | D8: Cleveland
A9: C0008 | B9: Female | C9: 42 | D9: Cleveland
A10: C0009 | B10: Female | C10: 25 | D10: Columbus
A11: C0010 | B11: Female | C11: 30 | D11: Cleveland
A12: C0011 | B12: Female | C12: 30 | D12: Cincinnati
A13: C0012 | B13: Female | C13: 28 | D13: Cincinnati
... A16: C0015 | B16: Female | C16: 43 | D16: Cleveland

Sheet Calculations
A1: 1/ KPI calculations
A3: Calculating Purchase per Call
A4: Customers | B4: Total_Calls | C4: Total_Purchase | D4: Purchase_per_Call
A5: {=_xlfn._xlws.SORT(_xlfn.UNIQUE(calls_2[Customer_ID]))} -> C0001 | B5: =COUNTIF(calls_2[Customer_ID],A5) -> 65 | C5: =SUMIF(calls_2[Customer_ID], A5, calls_2[Purchase_Amount]) -> 6785 | D5: =C5/B5 -> 104.38462
A6: C0002 | B6: =COUNTIF(calls_2[Customer_ID],A6) -> 63 | C6: =SUMIF(calls_2[Customer_ID], A6, calls_2[Purchase_Amount]) -> 5634 | D6: =C6/B6 -> 89.428571
A7: C0003 | B7: =COUNTIF(calls_2[Customer_ID],A7) -> 49 | C7: =SUMIF(calls_2[Customer_ID], A7, calls_2[Purchase_Amount]) -> 4758 | D7: =C7/B7 -> 97.102041
A8: C0004 | B8: =COUNTIF(calls_2[Customer_ID],A8) -> 82 | C8: =SUMIF(calls_2[Customer_ID], A8, calls_2[Purchase_Amount]) -> 7689 | D8: =C8/B8 -> 93.768293
A9: C0005 | B9: =COUNTIF(calls_2[Customer_ID],A9) -> 79 | C9: =SUMIF(calls_2[Customer_ID], A9, calls_2[Purchase_Amount]) -> 7747 | D9: =C9/B9 -> 98.063291
A10: C0006 | B10: =COUNTIF(calls_2[Customer_ID],A10) -> 61 | C10: =SUMIF(calls_2[Customer_ID], A10, calls_2[Purchase_Amount]) -> 6122 | D10: =C10/B10 -> 100.36066
A11: C0007 | B11: =COUNTIF(calls_2[Customer_ID],A11) -> 67 | C11: =SUMIF(calls_2[Customer_ID], A11, calls_2[Purchase_Amount]) -> 7216 | D11: =C11/B11 -> 107.70149
A12: C0008 | B12: =COUNTIF(calls_2[Customer_ID],A12) -> 58 | C12: =SUMIF(calls_2[Customer_ID], A12, calls_2[Purchase_Amount]) -> 4972 | D12: =C12/B12 -> 85.724138
A13: C0009 | B13: =COUNTIF(calls_2[Customer_ID],A13) -> 68 | C13: =SUMIF(calls_2[Customer_ID], A13, calls_2[Purchase_Amount]) -> 6569 | D13: =C13/B13 -> 96.602941
A14: C0010 | B14: =COUNTIF(calls_2[Customer_ID],A14) -> 72 | C14: =SUMIF(calls_2[Customer_ID], A14, calls_2[Purchase_Amount]) -> 6242 | D14: =C14/B14 -> 86.694444
A15: C0011 | B15: =COUNTIF(calls_2[Customer_ID],A15) -> 74 | C15: =SUMIF(calls_2[Customer_ID], A15, calls_2[Purchase_Amount]) -> 6749 | D15: =C15/B15 -> 91.202703
A16: C0012 | B16: =COUNTIF(calls_2[Customer_ID],A16) -> 70 | C16: =SUMIF(calls_2[Customer_ID], A16, calls_2[Purchase_Amount]) -> 6819 | D16: =C16/B16 -> 97.414286
A17: C0013 | B17: =COUNTIF(calls_2[Customer_ID],A17) -> 69 | C17: =SUMIF(calls_2[Customer_ID], A17, calls_2[Purchase_Amount]) -> 7230 | D17: =C17/B17 -> 104.78261
... A19: C0015 | B19: =COUNTIF(calls_2[Customer_ID],A19) -> 59 | C19: =SUMIF(calls_2[Customer_ID], A19, calls_2[Purchase_Amount]) -> 6518 | D19: =C19/B19 -> 110.47458
A22: Revenue per Representative | D22: Average Revenue per Customer | H22: Average Call Duration by Representative
A23: Representative | B23: Revenue | D23: Customer | E23: Revenue | H23: Representative | I23: Avg_Call_Duration
A24: {=_xlfn._xlws.SORT(_xlfn.UNIQUE(calls_2[Representative]))} -> R01 | B24: =SUMIF(calls_2[Representative],A24,calls_2[Purchase_Amount]) -> 18415 | D24: {=_xlfn._xlws.SORT(_xlfn.UNIQUE(calls_2[Customer_ID]))} -> C0001 | E24: =SUMIF(calls_2[Customer_ID], D24, calls_2[Purchase_Amount]) -> 6785 | H24: {=_xlfn._xlws.SORT(_xlfn.UNIQUE(calls_2[Representative]))} -> R01 | I24: =AVERAGEIFS(calls_2[Call_Duration],calls_2[Representative],H24) -> 89.068783
A25: R02 | B25: =SUMIF(calls_2[Representative],A25,calls_2[Purchase_Amount]) -> 20535 | D25: C0002 | E25: =SUMIF(calls_2[Customer_ID], D25, calls_2[Purchase_Amount]) -> 5634 | H25: R02 | I25: =AVERAGEIFS(calls_2[Call_Duration],calls_2[Representative],H25) -> 88.497696
A26: R03 | B26: =SUMIF(calls_2[Representative],A26,calls_2[Purchase_Amount]) -> 20818 | D26: C0003 | E26: =SUMIF(calls_2[Customer_ID], D26, calls_2[Purchase_Amount]) -> 4758 | H26: R03 | I26: =AVERAGEIFS(calls_2[Call_Duration],calls_2[Representative],H26) -> 85.237864
A27: R04 | B27: =SUMIF(calls_2[Representative],A27,calls_2[Purchase_Amount]) -> 16582 | D27: C0004 | E27: =SUMIF(calls_2[Customer_ID], D27, calls_2[Purchase_Amount]) -> 7689 | H27: R04 | I27: =AVERAGEIFS(calls_2[Call_Duration],calls_2[Representative],H27) -> 95.701087
A28: R05 | B28: =SUMIF(calls_2[Representative],A28,calls_2[Purchase_Amount]) -> 20104 | D28: C0005 | E28: =SUMIF(calls_2[Customer_ID], D28, calls_2[Purchase_Amount]) -> 7747 | H28: R05 | I28: =AVERAGEIFS(calls_2[Call_Duration],calls_2[Representative],H28) -> 91.045
D29: C0006 | E29: =SUMIF(calls_2[Customer_ID], D29, calls_2[Purchase_Amount]) -> 6122
D30: C0007 | E30: =SUMIF(calls_2[Customer_ID], D30, calls_2[Purchase_Amount]) -> 7216
D31: C0008 | E31: =SUMIF(calls_2[Customer_ID], D31, calls_2[Purchase_Amount]) -> 4972
D32: C0009 | E32: =SUMIF(calls_2[Customer_ID], D32, calls_2[Purchase_Amount]) -> 6569
D33: C0010 | E33: =SUMIF(calls_2[Customer_ID], D33, calls_2[Purchase_Amount]) -> 6242
D34: C0011 | E34: =SUMIF(calls_2[Customer_ID], D34, calls_2[Purchase_Amount]) -> 6749
D35: C0012 | E35: =SUMIF(calls_2[Customer_ID], D35, calls_2[Purchase_Amount]) -> 6819
D36: C0013 | E36: =SUMIF(calls_2[Customer_ID], D36, calls_2[Purchase_Amount]) -> 7230
D37: C0014 | E37: =SUMIF(calls_2[Customer_ID], D37, calls_2[Purchase_Amount]) -> 5404
D38: C0015 | E38: =SUMIF(calls_2[Customer_ID], D38, calls_2[Purchase_Amount]) -> 6518
A41: 2/ Lookups and Ranking
A42: Customer Satisfaction | E42: Total Spending for a selected customer using XLOOKUP()
A43: Customer | B43: Satisfaction | C43: Classification | E43: Customer | F43: Total_spending
A44: {=_xlfn._xlws.SORT(_xlfn.UNIQUE(calls_2[Customer_ID]))} -> C0001 | B44: =AVERAGEIF(calls_2[Customer_ID],A44,calls_2[Satisfaction_Rating]) -> 3.8307692 | C44: {=_xlfn.IFS(B44>=4.5, "Excellent",AND(B44 >=4,B44<=4.49), "Good", AND(B44 >=3,B44<=3.99), "Average", TRUE, "Poor")} -> Average | E44: {=_xlfn._xlws.SORT(_xlfn.UNIQUE(calls_2[Customer_ID]))} -> C0001 | F44: =_xlfn.XLOOKUP(E44,A5,C5,"not found",0) -> 6785
A45: C0002 | B45: =AVERAGEIF(calls_2[Customer_ID],A45,calls_2[Satisfaction_Rating]) -> 4.0730159 | C45: {=_xlfn.IFS(B45>=4.5, "Excellent",AND(B45 >=4,B45<=4.49), "Good", AND(B45 >=3,B45<=3.99), "Average", TRUE, "Poor")} -> Good | E45: C0002 | F45: =_xlfn.XLOOKUP(E45,A6,C6,"not found",0) -> 5634
A46: C0003 | B46: =AVERAGEIF(calls_2[Customer_ID],A46,calls_2[Satisfaction_Rating]) -> 4.0857143 | C46: {=_xlfn.IFS(B46>=4.5, "Excellent",AND(B46 >=4,B46<=4.49), "Good", AND(B46 >=3,B46<=3.99), "Average", TRUE, "Poor")} -> Good | E46: C0003 | F46: =_xlfn.XLOOKUP(E46,A7,C7,"not found",0) -> 4758
...

Sheet Pivot Tables
A2: Number of Calls for each Customer ID
A3: Row Labels | B3: Count of Call_Number
A4: C0001 | B4: 65
A5: C0002 | B5: 63
A6: C0003 | B6: 49
A7: C0004 | B7: 82
A8: C0005 | B8: 79
A9: C0006 | B9: 61
A10: C0007 | B10: 67
A11: C0008 | B11: 58
A12: C0009 | B12: 67
A13: C0010 | B13: 72
A14: C0011 | B14: 74
A15: C0012 | B15: 70
... A19: Grand Total | B19: 995
A23: Customer Satisfaction
A24: Row Labels | B24: Count of Call_Number | C24: Average of Satisfaction_Rating
A25: C0001 | B25: 65 | C25: 3.8307692
A26: C0002 | B26: 63 | C26: 4.0730159
A27: C0003 | B27: 49 | C27: 4.0857143
A28: C0004 | B28: 82 | C28: 3.9768293
A29: C0005 | B29: 79 | C29: 3.9797468
A30: C0006 | B30: 61 | C30: 3.8393443
A31: C0007 | B31: 67 | C31: 3.8522388
A32: C0008 | B32: 58 | C32: 3.9534483
A33: C0009 | B33: 67 | C33: 3.6656716
A34: C0010 | B34: 72 | C34: 3.8638889
A35: C0011 | B35: 74 | C35: 3.9837838
A36: C0012 | B36: 70 | C36: 4.13
... A40: Grand Total | B40: 995 | C40: 3.8986935
A44: Top 10 Customers
A45: Row Labels | B45: Sum of Purchase_Amount
A46: C0005 | B46: 7747
A47: C0004 | B47: 7689
A48: C0013 | B48: 7230
A49: C0007 | B49: 7216
A50: C0012 | B50: 6819
A51: C0001 | B51: 6785
A52: C0011 | B52: 6749
A53: C0009 | B53: 6529
...

Sheet Dashboard Portfolio
C1: CALL CENTER REPORT
Q17: ='Dashboard Pivots'!B109 -> R01 | R17: ='Dashboard Pivots'!C109 -> R02 | S17: ='Dashboard Pivots'!D109 -> R03 | T17: ='Dashboard Pivots'!E109 -> R04 | U17: ='Dashboard Pivots'!F109 -> R05 | V17: TOTAL
P18: ='Dashboard Pivots'!A110 -> Cincinnati
P19: ='Dashboard Pivots'!A111 -> C0003 | Q19: ='Dashboard Pivots'!B111 -> 891 | R19: ='Dashboard Pivots'!C111 -> 1286 | S19: ='Dashboard Pivots'!D111 -> 1282 | T19: ='Dashboard Pivots'!E111 -> 739 | U19: ='Dashboard Pivots'!F111 -> 560 | V19: ='Dashboard Pivots'!G111 -> 4758
P20: ='Dashboard Pivots'!A112 -> C0004 | Q20: ='Dashboard Pivots'!B112 -> 1991 | R20: ='Dashboard Pivots'!C112 -> 1886 | S20: ='Dashboard Pivots'!D112 -> 1206 | T20: ='Dashboard Pivots'!E112 -> 884 | U20: ='Dashboard Pivots'!F112 -> 1722 | V20: ='Dashboard Pivots'!G112 -> 7689
P21: ='Dashboard Pivots'!A113 -> C0011 | Q21: ='Dashboard Pivots'!B113 -> 1163 | R21: ='Dashboard Pivots'!C113 -> 1180 | S21: ='Dashboard Pivots'!D113 -> 1616 | T21: ='Dashboard Pivots'!E113 -> 1043 | U21: ='Dashboard Pivots'!F113 -> 1747 | V21: ='Dashboard Pivots'!G113 -> 6749
P22: ='Dashboard Pivots'!A114 -> C0012 | Q22: ='Dashboard Pivots'!B114 -> 1438 | R22: ='Dashboard Pivots'!C114 -> 1616 | S22: ='Dashboard Pivots'!D114 -> 866 | T22: ='Dashboard Pivots'!E114 -> 829 | U22: ='Dashboard Pivots'!F114 -> 2070 | V22: ='Dashboard Pivots'!G114 -> 6819
P23: ='Dashboard Pivots'!A115 -> Cleveland
P24: ='Dashboard Pivots'!A116 -> C0002 | Q24: ='Dashboard Pivots'!B116 -> 1233 | R24: ='Dashboard Pivots'!C116 -> 223 | S24: ='Dashboard Pivots'!D116 -> 1680 | T24: ='Dashboard Pivots'!E116 -> 990 | U24: ='Dashboard Pivots'!F116 -> 1508 | V24: ='Dashboard Pivots'!G116 -> 5634
P25: ='Dashboard Pivots'!A117 -> C0007 | Q25: ='Dashboard Pivots'!B117 -> 1598 | R25: ='Dashboard Pivots'!C117 -> 1907 | S25: ='Dashboard Pivots'!D117 -> 869 | T25: ='Dashboard Pivots'!E117 -> 1426 | U25: ='Dashboard Pivots'!F117 -> 1416 | V25: ='Dashboard Pivots'!G117 -> 7216
P26: ='Dashboard Pivots'!A118 -> C0008 | Q26: ='Dashboard Pivots'!B118 -> 900 | R26: ='Dashboard Pivots'!C118 -> 1016 | S26: ='Dashboard Pivots'!D118 -> 960 | T26: ='Dashboard Pivots'!E118 -> 903 | U26: ='Dashboard Pivots'!F118 -> 1193 | V26: ='Dashboard Pivots'!G118 -> 4972
P27: ='Dashboard Pivots'!A119 -> C0010 | Q27: ='Dashboard Pivots'!B119 -> 900 | R27: ='Dashboard Pivots'!C119 -> 1470 | S27: ='Dashboard Pivots'!D119 -> 1617 | T27: ='Dashboard Pivots'!E119 -> 1314 | U27: ='Dashboard Pivots'!F119 -> 941 | V27: ='Dashboard Pivots'!G119 -> 6242
P28: ='Dashboard Pivots'!A120 -> C0013 | Q28: ='Dashboard Pivots'!B120 -> 1255 | R28: ='Dashboard Pivots'!C120 -> 516 | S28: ='Dashboard Pivots'!D120 -> 1874 | T28: ='Dashboard Pivots'!E120 -> 1863 | U28: ='Dashboard Pivots'!F120 -> 1722 | V28: ='Dashboard Pivots'!G120 -> 7230
P29: ='Dashboard Pivots'!A121 -> C0015 | Q29: ='Dashboard Pivots'!B121 -> 1138 | R29: ='Dashboard Pivots'!C121 -> 1898 | S29: ='Dashboard Pivots'!D121 -> 1482 | T29: ='Dashboard Pivots'!E121 -> 846 | U29: ='Dashboard Pivots'!F121 -> 1154 | V29: ='Dashboard Pivots'!G121 -> 6518
P30: ='Dashboard Pivots'!A122 -> Columbus
P31: ='Dashboard Pivots'!A123 -> C0001 | Q31: ='Dashboard Pivots'!B123 -> 1655 | R31: ='Dashboard Pivots'!C123 -> 805 | S31: ='Dashboard Pivots'!D123 -> 2263 | T31: ='Dashboard Pivots'!E123 -> 987 | U31: ='Dashboard Pivots'!F123 -> 1075 | V31: ='Dashboard Pivots'!G123 -> 6785
P32: ='Dashboard Pivots'!A124 -> C0005 | Q32: ='Dashboard Pivots'!B124 -> 1104 | R32: ='Dashboard Pivots'!C124 -> 2280 | S32: ='Dashboard Pivots'!D124 -> 1445 | T32: ='Dashboard Pivots'!E124 -> 1722 | U32: ='Dashboard Pivots'!F124 -> 1196 | V32: ='Dashboard Pivots'!G124 -> 7747
P33: ='Dashboard Pivots'!A125 -> C0006 | Q33: ='Dashboard Pivots'!B125 -> 372 | R33: ='Dashboard Pivots'!C125 -> 1818 | S33: ='Dashboard Pivots'!D125 -> 1292 | T33: ='Dashboard Pivots'!E125 -> 1156 | U33: ='Dashboard Pivots'!F125 -> 1484 | V33: ='Dashboard Pivots'!G125 -> 6122
P34: ='Dashboard Pivots'!A126 -> C0009 | Q34: ='Dashboard Pivots'!B126 -> 1375 | R34: ='Dashboard Pivots'!C126 -> 1271 | S34: ='Dashboard Pivots'!D126 -> 1214 | T34: ='Dashboard Pivots'!E126 -> 1103 | U34: ='Dashboard Pivots'!F126 -> 1566 | V34: ='Dashboard Pivots'!G126 -> 6529
P35: ='Dashboard Pivots'!A127 -> C0014 | Q35: ='Dashboard Pivots'!B127 -> 1362 | R35: ='Dashboard Pivots'!C127 -> 1363 | S35: ='Dashboard Pivots'!D127 -> 1152 | T35: ='Dashboard Pivots'!E127 -> 777 | U35: ='Dashboard Pivots'!F127 -> 750 | V35: ='Dashboard Pivots'!G127 -> 5404

Sheet Dashboard Pivots
A3: Call Count | B3: Total Amount | C3: Total Duration | D3: Average Rating | E3: 5 Star Calls
A4: 995 | B4: 96414 | C4: 89301 | D4: 3.8986935 | E4: 248
A8: Show different KPIs using Representative slicer
A9: Call Count | B9: Total Amount | C9: Total Duration | D9: Average Rating | E9: 5 Star Calls
A10: 188 | B10: 18375 | C10: 16720 | D10: 3.9228723 | E10: 48
A17: Call Trend graph (Line + Area graph) | H17: Weekday Trend
A18: Row Labels | B18: Call Count | C18: Call Count2 | H18: Row Labels | I18: Call Count
A19: Jan | B19: 16 | C19: 16 | H19: Sunday | I19: 35
A20: Feb | B20: 14 | C20: 14 | H20: Monday | I20: 30
A21: Mar | B21: 26 | C21: 26 | H21: Tuesday | I21: 13
A22: Apr | B22: 29 | C22: 29 | H22: Wednesday | I22: 23
A23: May | B23: 17 | C23: 17 | H23: Thursday | I23: 23
A24: Jun | B24: 15 | C24: 15 | H24: Friday | I24: 24
A25: Jul | B25: 15 | C25: 15 | H25: Saturday | I25: 40
A26: Aug | B26: 7 | C26: 7 | H26: Grand Total | I26: 188
A27: Sep | B27: 11 | C27: 11
A28: Oct | B28: 24 | C28: 24
A29: Nov | B29: 9 | C29: 9
A30: Dec | B30: 5 | C30: 5
A31: Grand Total | B31: 188 | C31: 188
I38: Selected_Rep | J38: =A52 -> R01
A39: Calls and Amount by Representative | F39: For Graphs
A40: Row Labels | B40: Call Count | C40: Total Amount | F40: Repr | G40: Calls | H40: Amount | I40: Sel_Calls | J40: Sel_Amount
A41: R01 | B41: 188 | C41: 18375 | F41: {=A41:C45} -> R01 | G41: 188 | H41: 18375 | I41: =IF(F41=$J$38,G41,NA()) -> 188 | J41: =IF(F41=$J$38,H41,NA()) -> 18375
A42: R02 | B42: 217 | C42: 20535 | F42: R02 | G42: 217 | H42: 20535 | I42: =IF(F42=$J$38,G42,NA()) -> #N/A | J42: =IF(F42=$J$38,H42,NA()) -> #N/A
A43: R03 | B43: 206 | C43: 20818 | F43: R03 | G43: 206 | H43: 20818 | I43: =IF(F43=$J$38,G43,NA()) -> #N/A | J43: =IF(F43=$J$38,H43,NA()) -> #N/A
A44: R04 | B44: 184 | C44: 16582 | F44: R04 | G44: 184 | H44: 16582 | I44: =IF(F44=$J$38,G44,NA()) -> #N/A | J44: =IF(F44=$J$38,H44,NA()) -> #N/A
A45: R05 | B45: 200 | C45: 20104 | F45: R05 | G45: 200 | H45: 20104 | I45: =IF(F45=$J$38,G45,NA()) -> #N/A | J45: =IF(F45=$J$38,H45,NA()) -> #N/A
A46: Grand Total | B46: 995 | C46: 96414
A51: Row Labels
A52: R01
A66: Call Count | B66: Column Labels
A67: Row Labels | B67: Female | C67: Male | D67: Grand Total
A68: Cincinnati | B68: 144 | C68: 131 | D68: 275
A69: Cleveland | B69: 325 | C69: 63 | D69: 388
A70: Columbus | B70: 127 | C70: 205 | D70: 332
A71: Grand Total | B71: 596 | C71: 399 | D71: 995
A81: Row Labels | B81: Call Count
A82: 1 | B82: 1
A83: 2 | B83: 9
...

Sheet Icons
